{
  "timestamp": "2024-12-19T11:40:35.035131",
  "error_type": "AttributeError",
  "message": "module 'asyncio' has no attribute 'timeout'",
  "traceback": "Traceback (most recent call last):\n  File \"C:\\Users\\maxim\\.0Link\\penguin\\penguin\\utils\\test_error_handling.py\", line 60, in trigger_timeout\n    async with asyncio.timeout(0.1):\nAttributeError: module 'asyncio' has no attribute 'timeout'\n",
  "context": {
    "component": "tests",
    "method": "trigger_timeout",
    "timeout_value": 0.1,
    "sleep_value": 1.0
  },
  "severity": "ERROR"
}